Workbook
Name _ftnref1: 'Inhaltliche Bewertung - Angebot'!$U$53
Name _ftnref1: 'Inhaltliche Bewertung - GI'!$U$53
Name _ftnref2: 'Inhaltliche Bewertung - Angebot'!$U$65
Name _ftnref2: 'Inhaltliche Bewertung - GI'!$U$65
Name _ftnref3: 'Inhaltliche Bewertung - Angebot'!$E$74
Name _ftnref3: 'Inhaltliche Bewertung - GI'!$E$74
Name aig_MaxDeckungssumme: 'AIG Facility - Tarif'!$C$32
Name aig_MaxUmsatz: 'AIG Facility - Tarif'!$C$33
Name aig1usedClauses: 'Daten-Abzug'!$D$32
Name aig2usedClauses: 'Daten-Abzug'!$E$32
Name aig3usedClauses: 'Daten-Abzug'!$F$32
Name aigArbitrationCourtPercentage: Deckungsoptionen!$B$13
Name aigArbitrationCourtPremiumNeutral: Deckungsoptionen!$B$12
Name aigArbitrationCourtSelected: Deckungsoptionen!$B$11
Name aigDefaultKlauseln: 'Default-Klauseln'!$B$5
Name aigDoublePerYearPercentage: Deckungsoptionen!$B$8
Name aigDoublePerYearPremiumNeutral: Deckungsoptionen!$B$7
Name aigDoublePerYearSelected: Deckungsoptionen!$B$6
Name AIGFacilityAngeboteneDS: 'AIG Facility - Preisrechner'!$B$5:$G$5
Name AIGFacilityKriterien: Flussdiagramm!$L$10
Name AIGFacilityKriterien1: Flussdiagramm!$L$10
Name AIGFacilityKriterien2: Flussdiagramm!$M$10
Name AIGFacilityKriterien3: Flussdiagramm!$N$10
Name aigFacilityYesNo: 'Daten-Abzug'!$D$24
Name aigLimit1CoverageOptions: 'Daten-Abzug'!$D$31
Name aigLimit1FacilityYesNo: 'Daten-Abzug'!$D$24
Name aigLimit1HowdenNetProvision: 'Daten-Abzug'!$D$29
Name aigLimit1Offered: 'Daten-Abzug'!$D$27
Name aigLimit1Premium: 'Daten-Abzug'!$D$28
Name aigLimit1Stars: 'Daten-Abzug'!$D$25
Name aigLimit1Status: 'Daten-Abzug'!$D$33
Name aigLimit2CoverageOptions: 'Daten-Abzug'!$E$31
Name aigLimit2HowdenNetProvision: 'Daten-Abzug'!$E$29
Name aigLimit2Offered: 'Daten-Abzug'!$E$27
Name aigLimit2Premium: 'Daten-Abzug'!$E$28
Name aigLimit2Stars: 'Daten-Abzug'!$E$25
Name aigLimit2Status: 'Daten-Abzug'!$E$33
Name aigLimit3CoverageOptions: 'Daten-Abzug'!$F$31
Name aigLimit3HowdenNetProvision: 'Daten-Abzug'!$F$29
Name aigLimit3Offered: 'Daten-Abzug'!$F$27
Name aigLimit3Premium: 'Daten-Abzug'!$F$28
Name aigLimit3Stars: 'Daten-Abzug'!$F$25
Name aigLimit3Status: 'Daten-Abzug'!$F$33
Name AIGMax10Mio: Fragenkatalog!$K$63
Name aigUsedClauses: Fragenkatalog!$Z$6
Name aigWpHGPercentage: Deckungsoptionen!$B$18
Name aigWpHGPremiumNeutral: Deckungsoptionen!$B$17
Name aigWpHGSelected: Deckungsoptionen!$B$16
Name AnteileAnDerBörseGehandelt: Fragenkatalog!$K$61
Name Außenumsatz: Fragenkatalog!$K$57
Name AußenumsatzGI: Fragenkatalog!$F$57
Name axa_MaxDeckungssumme: 'AXA - Tarif ab 20230601'!$K$19
Name axa_MaxUmsatz: 'AXA - Tarif ab 20230601'!$K$20
Name axa_PremiumAdjustment: 'SIC-Liste'!$K$3
Name axa_Referral: 'SIC-Liste'!$J$3
Name axa1usedClauses: 'Daten-Abzug'!$D$22
Name axa2usedClauses: 'Daten-Abzug'!$E$22
Name axa3usedClauses: 'Daten-Abzug'!$F$22
Name axaArbitrationCourtPercentage: Deckungsoptionen!$D$13
Name axaArbitrationCourtPremiumNeutral: Deckungsoptionen!$D$12

Sheet Fragenkatalog
F1: 43557 | Q1: Anzahl Referrals | S1: Zu- / Abschläge | W1: Anzahl Referrals | Y1: Zu- / Abschläge | AC1: Anzahl Referrals | AE1: Zu- / Abschläge | AI1: Anzahl Referrals | AK1: Zu- / Abschläge | AO1: Anzahl Referrals | AQ1: Zu- / Abschläge | AU1: Anzahl Referrals | AW1: Zu- / Abschläge | BA1: Anzahl Referrals | BC1: Zu- / Abschläge | BG1: Anzahl Referrals | BI1: Zu- / Abschläge | BM1: Anzahl Referrals | BO1: Zu- / Abschläge
F2: 0.47 | Q2: =COUNTIF(Q7:Q148,"Referral") -> 1 | S2: =SUM(S7:S210) -> 0 | W2: =COUNTIF(W7:W148,"Referral") -> 1 | Y2: =SUM(Y7:Y210) -> 0 | AC2: =COUNTIF(AC8:AC148,"Referral") -> 2 | AE2: =SUM(AE7:AE210) -> 0 | AI2: =COUNTIF(AI7:AI148,"Referral") -> 2 | AK2: =SUM(AK7:AK210) -> 0 | AO2: =COUNTIF(AO7:AO148,"Referral") -> 1 | AQ2: =SUM(AQ7:AQ210) -> 0 | AU2: =COUNTIF(AU7:AU148,"Referral") -> 1 | AW2: =SUM(AW7:AW210) -> 0 | BA2: =COUNTIF(BA7:BA148,"Referral") -> 0 | BC2: =SUM(BC7:BC210) -> 0 | BG2: =COUNTIF(BG8:BG148,"Referral") -> 0 | BI2: =SUM(BI7:BI210) -> 0
F3: Philipp Thier | AI3: =NewlineEigenkapitalquote -> 0 | AU3: =WVAGEigenkapitalquote -> 0
F4: Grobindikation | K4: Angebotsindikation | P4: DUAL | V4: AIG Facility | AB4: Berkley | AH4: Newline | AN4: AXA | AT4: WVAG | AZ4: Markel | BF4: Liberty | BL4: Ergo
A5: Struktur für Testfälle | B5: Nr: Frage | C5: Fragebogen / Tasks | D5: Frage | E5: Folgefrage | F5: Hilfsspalte 1 für zusätzliche Berechnungen | G5: DigPos- ODER Testfall-Daten | H5: Mögliche Antwort-Optionen | I5: Zellen-Name für DigPos-Input | J5: Hilfsspalte 2 für zusätzliche Berechnungen | K5: Hilfsspalte 1 für zusätzliche Berechnungen | L5: DigPos- ODER Testfall-Daten | M5: Mögliche Antwort-Optionen | N5: Zellen-Name für DigPos-Input | O5: Hilfsspalte 2 für zusätzliche Berechnungen | P5: Dunkelverarbeitung / Referral / KO | Q5: Refferal Triggers | R5: KO Triggers | S5: Zu- und Abschläge | T5: Klauseln | U5: Limit für DS | V5: Dunkelverarbeitung / Referral / KO | W5: Refferal Triggers | X5: KO Triggers | Y5: Zu- und Abschläge | Z5: Klauseln | AA5: Limit für DS | AB5: Dunkelverarbeitung / Referral / KO | AC5: Refferal Triggers | AD5: KO Triggers | AE5: Zu- und Abschläge | AF5: Klauseln | AG5: Limit für DS | AH5: Dunkelverarbeitung / Referral / KO | AI5: Refferal Triggers | AJ5: KO Triggers | AK5: Zu- und Abschläge | AL5: Klauseln | AM5: Limit für DS | AN5: Dunkelverarbeitung / Referral / KO | AO5: Refferal Triggers | AP5: KO Triggers | AQ5: Zu- und Abschläge | AR5: Klauseln | AS5: Limit für DS | AT5: Dunkelverarbeitung / Referral / KO | AU5: Refferal Triggers | AV5: KO Triggers | AW5: Zu- und Abschläge | AX5: Klauseln | AY5: Limit für DS | AZ5: Dunkelverarbeitung / Referral / KO | BA5: Refferal Triggers | BB5: KO Triggers | BC5: Zu- und Abschläge | BD5: Klauseln | BE5: Limit für DS | BF5: Dunkelverarbeitung / Referral / KO | BG5: Refferal Triggers | BH5: KO Triggers | BI5: Zu- und Abschläge | BJ5: Klauseln | BK5: Limit für DS | BL5: Dunkelverarbeitung / Referral / KO | BM5: Refferal Triggers | BN5: KO Triggers | BO5: Zu- und Abschläge | BP5: Klauseln | BQ5: Limit für DS | BR5: Fachliche Beschreibung der Referralgründe
P6: =IF(R6>0,OfferDeclined,IF(Q6>0,OfferReferral,OfferReady)) -> OFFER_REFERRAL | Q6: =COUNTIF(Q7:Q151,Referral) -> 1 | R6: =COUNTIF(R7:R151,"KO Trigger") -> 0 | S6: =SUM(S7:S151) -> 0 | T6: =CONCATENATE(T24,",",dualDefaultKlauseln) -> , | U6: =MIN(U7:U151) -> 0 | V6: =IF(X6>0,OfferDeclined,IF(W6>0,OfferReferral,OfferReady)) -> OFFER_REFERRAL | W6: =COUNTIF(W7:W151,Referral) -> 1 | X6: =COUNTIF(X7:X151,"KO Trigger") -> 0 | Y6: =SUM(Y7:Y151) -> 0 | Z6: =CONCATENATE(Z24,",",aigDefaultKlauseln) -> , | AA6: =MIN(AA7:AA151) -> 0 | AB6: =IF(AD6>0,OfferDeclined,IF(AC6>0,OfferReferral,OfferReady)) -> OFFER_REFERRAL | AC6: =COUNTIF(AC7:AC151,Referral) -> 2 | AD6: =COUNTIF(AD7:AD151,"KO Trigger") -> 0 | AE6: =SUM(AE7:AE151) -> 0 | AF6: =CONCATENATE(AF24,",",berkleyDefaultKlauseln) -> , | AG6: =MIN(AG7:AG151) -> 0 | AH6: =IF(AJ6>0,OfferDeclined,IF(AI6>0,OfferReferral,OfferReady)) -> OFFER_REFERRAL | AI6: =COUNTIF(AI7:AI151,Referral) -> 3 | AJ6: =COUNTIF(AJ7:AJ151,"KO Trigger") -> 0 | AK6: =SUM(AK7:AK151) -> 0 | AL6: =CONCATENATE(AL24,",",newlineDefaultKlauseln) -> , | AM6: =MIN(AM7:AM151) -> 0 | AN6: =IF(AP6>0,OfferDeclined,IF(AO6>0,OfferReferral,OfferReady)) -> OFFER_DECLINED | AO6: =COUNTIF(AO7:AO151,Referral) -> 2 | AP6: =COUNTIF(AP7:AP151,"KO Trigger") + IF(COUNTIF(AO53:AO59,"Referral")>1,1,0) -> 1 | AQ6: =SUM(AQ7:AQ151) -> 0 | AR6: =CONCATENATE(AR24,",",AR150,",",axaDefaultKlauseln) -> ,, | AS6: =MIN(AS7:AS151) -> 0 | AT6: =IF(AV6>0,OfferDeclined,IF(AU6>0,OfferReferral,OfferReady)) -> OFFER_REFERRAL | AU6: =COUNTIF(AU7:AU151,Referral) -> 1 | AV6: =COUNTIF(AV7:AV151,"KO Trigger") -> 0 | AW6: =SUM(AW7:AW151) -> 0 | AX6: =CONCATENATE(AX24,",",wvagDefaultKlauseln) -> , | AY6: =MIN(AY7:AY151) -> 0 | AZ6: =IF(BB6>0,OfferDeclined,IF(BA6>0,OfferReferral,OfferReady)) -> OFFER_DECLINED | BA6: =COUNTIF(BA7:BA151,Referral) -> 0 | BB6: =COUNTIF(BB7:BB151,"KO Trigger") -> 1 | BC6: =SUM(BC7:BC151) -> 0 | BD6: =CONCATENATE(BD24, ",",markelDefaultKlauseln) -> , | BE6: =MIN(BE7:BE151) -> 0 | BF6: =IF(BH6>0,OfferDeclined,IF(BG6>0,OfferReferral,OfferReady)) -> OFFER_READY_FOR_POLICY | BG6: =COUNTIF(BG7:BG151,Referral) -> 0 | BH6: =COUNTIF(BH7:BH151,"KO Trigger") -> 0 | BI6: =SUM(BI7:BI151) -> 0 | BJ6: =CONCATENATE(BJ24,",",libertyDefaultKlauseln) -> , | BK6: =MIN(BK7:BK151) -> 0 | BL6: =IF(BN6>0,OfferDeclined,IF(BM6>0,OfferReferral,OfferReady)) -> OFFER_DECLINED | BM6: =COUNTIF(BM7:BM151,Referral) -> 1 | BN6: =COUNTIF(BN7:BN151,"KO Trigger") -> 1 | BO6: =SUM(BO7:BO151) -> 0 | BP6: =CONCATENATE(BP24,BP34,",",BP149,",",ergoDefaultKlauseln) -> ,ergo_nettoisierung:group-4, | BR6: Referral | BS6: KO
A7: Risikofragen | B7: Stamm-Daten1 | C7: Stamm-Daten | D7: Name | H7: Text | M7: Text | N7: Stamm-Daten1 | P7: Dunkelverarbeitung | V7: Dunkelverarbeitung | AB7: Dunkelverarbeitung | AH7: Dunkelverarbeitung | AN7: Dunkelverarbeitung | AT7: Dunkelverarbeitung | AZ7: Dunkelverarbeitung | BF7: Dunkelverarbeitung | BL7: Dunkelverarbeitung | BS7: =BR7 -> 0
A8: Risikofragen | B8: StammDaten2 | C8: StammDaten | D8: Rechtsform | F8: =VLOOKUP(TEXT(giLegalForm,0),'Listen-Daten DigPos'!G3:H43,2,FALSE) -> andere | H8: Siehe Listen-Daten DigPos | I8: giLegalForm | J8: =VLOOKUP(F8,'Listen-Daten'!A2:B41,2,FALSE) -> #N/A | K8: =VLOOKUP(TEXT(StammDaten2,0),'Listen-Daten DigPos'!G3:H43,2,FALSE) -> andere | M8: Siehe Listen-Daten DigPos | N8: StammDaten2 | O8: =_xlfn.IFNA(VLOOKUP(K8,'Listen-Daten'!A2:B41,2,FALSE),"") | P8: Trigger | Q8: =IF(K8 ="Einzelunternehmen", Referral, Dunkelverarbeitung) -> Dunkelverarbeitung | V8: Trigger | W8: =IF(K8="Einzelunternehmen", Referral, Dunkelverarbeitung) -> Dunkelverarbeitung | AB8: Trigger | AC8: =IF(K8="Einzelunternehmen", Referral, Dunkelverarbeitung) -> Dunkelverarbeitung | AH8: Dunkelverarbeitung | AI8: =IF(OR($K$8="PartG",$K$8="GbR"), Referral, Dunkelverarbeitung) -> Dunkelverarbeitung | AN8: Trigger | AO8: =IF(K8="Einzelunternehmen", Referral, Dunkelverarbeitung) -> Dunkelverarbeitung | AT8: Trigger | AU8: =IF(OR(K8= "gGmbH",K8 ="gAG",K8 ="UG",K8 ="Einzelunternehmen"), Referral, Dunkelverarbeitung) -> Dunkelverarbeitung | AV8: =IF(K8= "GbR", "KO Trigger", Dunkelverarbeitung) -> Dunkelverarbeitung | AZ8: Trigger | BB8: =IF(OR(K8="Einzelunternehmen",K8="e.K."),KO_Trigger, Dunkelverarbeitung) -> Dunkelverarbeitung | BF8: Trigger | BG8: =IF(K8 ="Einzelunternehmen", Referral, Dunkelverarbeitung) -> Dunkelverarbeitung | BL8: Trigger | BM8: =IF(OR(K8= "LLP",K8 ="GbR",K8 ="KG",K8="OHG",K8 ="Einzelunternehmen"), Referral, Dunkelverarbeitung) -> Dunkelverarbeitung | BR8: Rechtsform | BS8: Rechtsform
A9: Risikofragen | B9: StammDaten10 | C9: StammDaten | D9: Rechtsform - Klarname | N9: StammDaten10 | P9: Dunkelverarbeitung | V9: Dunkelverarbeitung | AB9: Dunkelverarbeitung | AH9: Dunkelverarbeitung | AN9: Dunkelverarbeitung | AT9: Dunkelverarbeitung | AZ9: Dunkelverarbeitung | BF9: Dunkelverarbeitung | BL9: Dunkelverarbeitung | BS9: =BR9 -> 0
A10: Risikofragen | B10: StammDaten901 | C10: StammDaten | D10: Gemeinnützigkeit? | H10: yes / no | K10: =IF(L10="YES","ja",IF(L10="NO","nein","")) | M10: yes / no | N10: StammDaten901 | P10: Dunkelverarbeitung | V10: Dunkelverarbeitung | AB10: Dunkelverarbeitung | AH10: Dunkelverarbeitung | AN10: Dunkelverarbeitung | AT10: Dunkelverarbeitung | AZ10: Dunkelverarbeitung | BF10: Dunkelverarbeitung | BL10: Dunkelverarbeitung | BS10: =BR10 -> 0
A11: Risikofragen | B11: RisikoFragen127 | C11: RisikoFragen | D11: Wie hoch war die Bilanzsumme / das Vereinsvermögen (nur für Vereine)? | F11: =giClubRevenue -> 0 | H11: Zahlen | I11: giClubRevenue | K11: =RisikoFragen127 -> 0 | M11: Zahlen | N11: RisikoFragen127 | P11: Dunkelverarbeitung | V11: Dunkelverarbeitung | AB11: Dunkelverarbeitung | AH11: Dunkelverarbeitung | AN11: Dunkelverarbeitung | AT11: Trigger | AU11: =IF(RisikoFragen127 > 50000000,Referral,Dunkelverarbeitung) -> Dunkelverarbeitung | AV11: =IF(RisikoFragen127 > 500000000,"KO Trigger",Dunkelverarbeitung) -> Dunkelverarbeitung | AZ11: Dunkelverarbeitung | BF11: Dunkelverarbeitung | BL11: Dunkelverarbeitung | BR11: Hohe Bilanzsumme bzw. Vereinsvermöge | BS11: =BR11 -> Hohe Bilanzsumme bzw. Vereinsvermöge
A12: Risikofragen | B12: RisikoFragenVereine103 | C12: RisikoFragenVereine | D12: Betreibt die VN unmittelbar oder mittelbar durch abhängige Unternehmen lizenzabhängigen Profisport in den dazu geschaffenen Sportverbandsystem? | H12: yes / no | K12: =IF(L12="YES","ja",IF(L12="NO","nein","")) | M12: yes / no | N12: RisikoFragenVereine103 | P12: Trigger | Q12: =IF(K12=JaAntwort,Referral,Dunkelverarbeitung) -> Dunkelverarbeitung | V12: Dunkelverarbeitung | AB12: Trigger | AC12: =IF(Profisport=JaAntwort,"Referral",Dunkelverarbeitung) -> Dunkelverarbeitung | AH12: Trigger | AJ12: =IF(K12=JaAntwort,"KO Trigger",Dunkelverarbeitung) -> Dunkelverarbeitung | AN12: Trigger | AP12: =IF(Profisport=JaAntwort,"KO Trigger",Dunkelverarbeitung) -> Dunkelverarbeitung | AT12: Trigger | AV12: =IF(Profisport=JaAntwort,"KO Trigger",Dunkelverarbeitung) -> Dunkelverarbeitung | AZ12: Trigger | BA12: =IF(K12=JaAntwort,Referral,Dunkelverarbeitung) -> Dunkelverarbeitung | BF12: Trigger | BH12: =IF(Profisport=JaAntwort,"KO Trigger",Dunkelverarbeitung) -> Dunkelverarbeitung | BL12: Trigger | BN12: =IF(Profisport=JaAntwort,"KO Trigger",Dunkelverarbeitung) -> Dunkelverarbeitung | BR12: Profisport | BS12: =BR12 -> Profisport
A13: Risikofragen | B13: RisikoFragen11 | C13: RisikoFragen | D13: Branche | F13: =VLOOKUP(giBusinessCode,'Listen-Daten DigPos'!D3:E1102,2,FALSE) -> #N/A | H13: Siehe Listen-Daten DigPos | I13: giBusinessCode | K13: =IF(BusinessCode="","",VLOOKUP(BusinessCode,'Listen-Daten DigPos'!D3:E1102,2,FALSE)) | M13: Siehe Listen-Daten DigPos | N13: RisikoFragen11 | O13: =IF(K13="","",VLOOKUP(K13,'SIC-Liste'!B7:C1013,2,FALSE)) | P13: Trigger | Q13: =IF('SIC-Liste'!D3=Referral,Referral,Dunkelverarbeitung) -> Dunkelverarbeitung | R13: =IF('SIC-Liste'!D3=KO_Trigger,KO_Trigger,Dunkelverarbeitung) -> Dunkelverarbeitung | S13: ='SIC-Liste'!E3 -> 0 | V13: ??? | W13: ??? | X13: ??? | AB13: Trigger | AC13: =IF('SIC-Liste'!H3=Referral,Referral,Dunkelverarbeitung) -> Dunkelverarbeitung | AD13: =IF('SIC-Liste'!H3=KO_Trigger,KO_Trigger,Dunkelverarbeitung) -> Dunkelverarbeitung | AE13: ='SIC-Liste'!I3 -> 0 | AH13: Trigger | AI13: =IF('SIC-Liste'!F3=Referral,Referral,Dunkelverarbeitung) -> Dunkelverarbeitung | AJ13: =IF('SIC-Liste'!F3=KO_Trigger,KO_Trigger,Dunkelverarbeitung) -> Dunkelverarbeitung | AK13: ='SIC-Liste'!G3 -> 0 | AN13: Trigger | AO13: =IF('SIC-Liste'!J3=Referral,Referral,Dunkelverarbeitung) -> Dunkelverarbeitung | AP13: =IF('SIC-Liste'!J3=KO_Trigger,KO_Trigger,Dunkelverarbeitung) -> Dunkelverarbeitung | AQ13: ='SIC-Liste'!K3 -> 0 | AT13: Trigger | AU13: =IF('SIC-Liste'!L3=Referral,Referral,Dunkelverarbeitung) -> Dunkelverarbeitung | AV13: =IF('SIC-Liste'!L3=KO_Trigger,KO_Trigger,Dunkelverarbeitung) -> Dunkelverarbeitung | AW13: ='SIC-Liste'!M3 -> 0 | AZ13: Trigger | BA13: =IF('SIC-Liste'!R3=Referral,Referral,Dunkelverarbeitung) -> Dunkelverarbeitung | BB13: =IF('SIC-Liste'!R3=KO_Trigger,KO_Trigger,Dunkelverarbeitung) -> Dunkelverarbeitung | BC13: ='SIC-Liste'!S3 -> 0 | BF13: Trigger | BG13: =IF('SIC-Liste'!T2=Referral,Referral,Dunkelverarbeitung) -> Dunkelverarbeitung | BH13: =IF('SIC-Liste'!T2=KO_Trigger,KO_Trigger,Dunkelverarbeitung) -> Dunkelverarbeitung | BI13: ='SIC-Liste'!U2 -> 0 | BL13: Trigger | BM13: =IF('SIC-Liste'!X3=Referral,Referral,Dunkelverarbeitung) -> Dunkelverarbeitung | BN13: =IF('SIC-Liste'!X3=KO_Trigger,KO_Trigger,Dunkelverarbeitung) -> Dunkelverarbeitung | BO13: ='SIC-Liste'!Y3 -> 0 | BR13: Branche | BS13: =BR13 -> Branche
A14: Risikofragen | B14: RisikoFragen2 | C14: RisikoFragen | D14: Branche - Klarname | N14: RisikoFragen2 | P14: Dunkelverarbeitung | V14: Dunkelverarbeitung | AB14: Dunkelverarbeitung | AH14: Dunkelverarbeitung | AN14: Dunkelverarbeitung | AT14: Dunkelverarbeitung | AZ14: Dunkelverarbeitung | BF14: Dunkelverarbeitung | BL14: Dunkelverarbeitung | BS14: =BR14 -> 0
A15: Risikofragen | B15: RisikoFragen9 | C15: RisikoFragen | D15: Ist die Gesellschaft länger als 2 Jahre ohne Unterbrechung tätig? | H15: STARTUP / NOSTARTUP | K15: =IFERROR(VLOOKUP(L15,'Listen-Daten DigPos'!J3:K4,2,FALSE),"") | M15: STARTUP / NOSTARTUP | N15: RisikoFragen9 | O15: =K15 | P15: Trigger | Q15: =IF(RisikoFragen9="STARTUP",Referral,Dunkelverarbeitung) -> Dunkelverarbeitung | S15: =IF(K15='Listen-Daten'!F2,0.25,"") | V15: Trigger | W15: =IF(RisikoFragen9="STARTUP",Referral,Dunkelverarbeitung) -> Dunkelverarbeitung | Y15: =IF(RisikoFragen9="STARTUP",60%,"") | AA15: =IF(RisikoFragen9="STARTUP",1000000,"") | AB15: Trigger | AC15: =IF(RisikoFragen9="STARTUP",Referral,Dunkelverarbeitung) -> Dunkelverarbeitung | AE15: =IF(K15='Listen-Daten'!F2,30%,"") | AH15: Trigger | AK15: =IF(RisikoFragen9="STARTUP",0.5,0) -> 0 | AN15: Trigger | AP15: =IF(K15='Listen-Daten'!F2,"KO Trigger",Dunkelverarbeitung) -> Dunkelverarbeitung | AT15: Trigger | AU15: =IF(RisikoFragen9="STARTUP",Referral,Dunkelverarbeitung) -> Dunkelverarbeitung | AZ15: Trigger | BA15: =IF(RisikoFragen9="STARTUP",Referral,Dunkelverarbeitung) -> Dunkelverarbeitung | BE15: =IF(BA15=Referral,"1000000","") | BF15: Trigger | BH15: =IF(RisikoFragen9="STARTUP","KO Trigger",Dunkelverarbeitung) -> Dunkelverarbeitung | BL15: Trigger | BQ15: =IF(BM15=Referral,"1000000","") | BR15: Junges Unternehmen / Startup | BS15: =BR15 -> Junges Unternehmen / Startup
A16: Risikofragen | B16: Gruendungsjahr | C16: RisikoFragen | D16: Wann wurde die Firma gegründet? | K16: =L16 -> 0 | M16: Datum | N16: Gruendungsjahr | P16: Dunkelverarbeitung | V16: Dunkelverarbeitung | AB16: Dunkelverarbeitung | AH16: Dunkelverarbeitung | AN16: Dunkelverarbeitung | AT16: Dunkelverarbeitung | AZ16: Dunkelverarbeitung | BF16: Dunkelverarbeitung | BL16: Trigger | BN16: =IF(TYPE(K16)=1,IF(AND(DATEDIF(K16, TODAY(), "Y")>=2,DATEDIF(K16, TODAY(), "MD")>=0),Dunkelverarbeitung,"KO Trigger"),IF(_xlfn.NUMBERVALUE(RIGHT(K16,4))<=1900,Dunkelverarbeitung,"KO Trigger")) -> Dunkelverarbeitung | BR16: Gründungsjahr | BS16: =BR16 -> Gründungsjahr
A17: Risikofragen | B17: StammDaten3 | C17: StammDaten | D17: Land | H17: Siehe Listen-Daten DigPos | K17: =VLOOKUP(StammDaten3,'Listen-Daten'!H2:J250,3,FALSE) -> #N/A | M17: Siehe Listen-Daten DigPos | N17: StammDaten3 | P17: Trigger | R17: =IF(K17<>"Germany","KO Trigger",Dunkelverarbeitung) -> #N/A | V17: Trigger | X17: =IF(K17<>"Germany","KO Trigger",Dunkelverarbeitung) -> #N/A | AB17: Trigger | AD17: =IF(K17<>"Germany","KO Trigger",Dunkelverarbeitung) -> #N/A | AH17: Trigger | AI17: =IF(VLOOKUP(StammDaten3,'Listen-Daten'!$H$2:$K$250,4,FALSE)<>"EU",Referral,Dunkelverarbeitung) -> #N/A | AN17: Trigger | AP17: =IF(K17<>"Germany","KO Trigger",Dunkelverarbeitung) -> #N/A | AT17: Trigger | AV17: =IF(K17="Germany", Dunkelverarbeitung,"KO Trigger") -> #N/A | AZ17: Trigger | BA17: =IF(OR(K17="Germany",K17="Austria"),Dunkelverarbeitung,Referral) -> #N/A | BB17: =IF(OR(K17="Germany",K17="Austria",K17="Switzerland"),Dunkelverarbeitung,"KO Trigger") -> #N/A | BF17: Trigger | BH17: =IF(K17="Germany",Dunkelverarbeitung,"KO Trigger") -> #N/A | BL17: Trigger | BM17: =IF(K17="Germany",Dunkelverarbeitung,IF(VLOOKUP(StammDaten3,'Listen-Daten'!$H$2:$K$250,4,FALSE)="EU",Referral,"")) -> #N/A | BN17: =IF(VLOOKUP(StammDaten3,'Listen-Daten'!$H$2:$K$250,4,FALSE)<>"EU",KO_Trigger,"") -> #N/A | BR17: Land der Versicherungsnehmerin | BS17: =BR17 -> Land der Versicherungsnehmerin
A18: Risikofragen | B18: Stamm-Daten4 | C18: Stamm-Daten | D18: Strasse | H18: Text | M18: Text | N18: Stamm-Daten4 | P18: Dunkelverarbeitung | V18: Dunkelverarbeitung | AB18: Dunkelverarbeitung | AH18: Dunkelverarbeitung | AN18: Dunkelverarbeitung | AT18: Dunkelverarbeitung | AZ18: Dunkelverarbeitung | BF18: Dunkelverarbeitung | BL18: Dunkelverarbeitung | BS18: =BR18 -> 0
A19: Risikofragen | B19: Stamm-Daten5 | C19: Stamm-Daten | D19: PLZ | H19: Zahlen | M19: Zahlen | N19: Stamm-Daten5 | P19: Dunkelverarbeitung | V19: Dunkelverarbeitung | AB19: Dunkelverarbeitung | AH19: Dunkelverarbeitung | AN19: Dunkelverarbeitung | AT19: Dunkelverarbeitung | AZ19: Dunkelverarbeitung | BF19: Dunkelverarbeitung | BL19: Dunkelverarbeitung | BS19: =BR19 -> 0
A20: Risikofragen | B20: Stamm-Daten6 | C20: Stamm-Daten | D20: Stadt | H20: Text | M20: Text | N20: Stamm-Daten6 | P20: Dunkelverarbeitung | V20: Dunkelverarbeitung | AB20: Dunkelverarbeitung | AH20: Dunkelverarbeitung | AN20: Dunkelverarbeitung | AT20: Dunkelverarbeitung | AZ20: Dunkelverarbeitung | BF20: Dunkelverarbeitung | BL20: Dunkelverarbeitung | BS20: =BR20 -> 0
A21: Risikofragen | B21: RisikoFragen7 | C21: RisikoFragen | D21: Internet (webadresse) | H21: Text | K21: =IF(L21="YES","ja",IF(L21="NO","nein","")) | M21: Text | N21: RisikoFragen7 | P21: Dunkelverarbeitung | V21: Dunkelverarbeitung | AB21: Dunkelverarbeitung | AH21: Dunkelverarbeitung | AN21: Dunkelverarbeitung | AT21: Dunkelverarbeitung | AZ21: Dunkelverarbeitung | BF21: Dunkelverarbeitung | BL21: Dunkelverarbeitung | BS21: =BR21 -> 0
A22: Risikofragen | B22: RisikoFragen8 | C22: RisikoFragen | D22: Jahresabschluss Online? | H22: Text | K22: =IF(L22="YES","ja",IF(L22="NO","nein","")) | M22: Text | N22: RisikoFragen8 | P22: Dunkelverarbeitung | V22: Dunkelverarbeitung | AB22: Dunkelverarbeitung | AH22: Dunkelverarbeitung | AN22: Dunkelverarbeitung | AT22: Dunkelverarbeitung | AZ22: Dunkelverarbeitung | BF22: Dunkelverarbeitung | BL22: Dunkelverarbeitung | BS22: =BR22 -> 0
A23: Risikofragen | B23: RisikoFragen0a | C23: RisikoFragen | D23: Gewünschter Policen Beginn | E23: x | H23: Datum | K23: =RisikoFragen0a -> 0 | M23: Datum | N23: RisikoFragen0a | P23: Trigger | Q23: =IF(OR(PolicenBeginn<(TODAY()+3),PolicenBeginn>(TODAY()+90)),Referral,Dunkelverarbeitung) -> Referral | V23: Trigger | W23: =IF(PolicenBeginn<(TODAY()+3),Referral,Dunkelverarbeitung) -> Referral | AB23: Trigger | AC23: =IF(OR(PolicenBeginn<(TODAY()-30),PolicenBeginn>(TODAY()+90)),Referral,Dunkelverarbeitung) -> Referral | AH23: Trigger | AI23: =IF(OR(PolicenBeginn<(TODAY()-7),PolicenBeginn>(TODAY()+4*30)),Referral,Dunkelverarbeitung) -> Referral | AN23: Trigger | AO23: =IF(PolicenBeginn<(TODAY()+3),Referral,Dunkelverarbeitung) -> Referral | AT23: Trigger | AU23: =IF(OR(AND(Vorversicherung=JaAntwort,PolicenBeginn<(TODAY()-3*30)),AND(Vorversicherung=NeinAntwort,PolicenBeginn<(TODAY()-2*30))),Referral,Dunkelverarbeitung) -> Dunkelverarbeitung | AZ23: Trigger | BB23: =IF(OR(PolicenBeginn<(TODAY()-3*30),PolicenBeginn>(TODAY()+12*30)),"KO Trigger",Dunkelverarbeitung) -> KO Trigger | BF23: Trigger | BG23: =IF(PolicenBeginn>(EDATE(TODAY(),6)),Referral,Dunkelverarbeitung) -> Dunkelverarbeitung | BL23: Dunkelverarbeitung | BR23: Policenbeginn | BS23: =BR23 -> Policenbeginn
A24: Risikofragen | B24: RisikoFragen0b | C24: RisikoFragen | D24: Gewünschtes Policen Ende | H24: Datum | K24: =L24 -> 0 | M24: Datum | N24: RisikoFragen0b | P24: Trigger | Q24: =IF(RisikoFragen0b>DATE(YEAR(PolicenBeginn)+1,MONTH(PolicenBeginn),DAY(PolicenBeginn)),"Referral",Dunkelverarbeitung) -> Dunkelverarbeitung | T24: =IF(DAYS360(PolicenBeginn,PolicenAblauf)>=30*18,"bdv-871:group-4","") | V24: Dunkelverarbeitung | Z24: =IF(DAYS360(PolicenBeginn,PolicenAblauf)>=30*18,"bdv-811:group-4","") | AB24: Trigger | AC24: =IF(OR(DAYS360(PolicenBeginn,PolicenAblauf)<30*6,DAYS360(PolicenBeginn,PolicenAblauf)>=30*18),"Referral",Dunkelverarbeitung) -> Referral | AE24: =IF(DAYS360(PolicenBeginn,PolicenAblauf)>=30*18,0.1,0) -> 0 | AF24: =IF(DAYS360(PolicenBeginn,PolicenAblauf)>=30*18,"bdv-1351:group-4","") | AH24: Trigger | AI24: =IF(OR(DAYS360(PolicenBeginn,PolicenAblauf)<30*9,DAYS360(PolicenBeginn,PolicenAblauf)>30*24),Referral,Dunkelverarbeitung) -> Referral | AL24: =IF(DAYS360(PolicenBeginn,PolicenAblauf)>=30*18,"axa_my:group-4","") | AN24: Trigger | AP24: =IF(OR(PolicenAblauf<DATE(YEAR(PolicenBeginn)+1,MONTH(PolicenBeginn),DAY(PolicenBeginn)),PolicenAblauf>DATE(YEAR(PolicenBeginn),MONTH(PolicenBeginn)+24,DAY(PolicenBeginn))),"KO Trigger",Dunkelverarbeitung) -> KO Trigger | AR24: =IF(DAYS360(PolicenBeginn,PolicenAblauf)>=30*18,"axa_my:group-4","") | AT24: Trigger | AU24: =IF(DAYS360(PolicenBeginn,PolicenAblauf) <= 14*30,Dunkelverarbeitung,Referral) -> Dunkelverarbeitung | AX24: =IF(DAYS360(PolicenBeginn,PolicenAblauf)>=30*18,"bdv-901:group-4","") | AZ24: Trigger | BA24: =IF(DAYS360(PolicenBeginn,PolicenAblauf)<=12*30,Dunkelverarbeitung,Referral) -> Dunkelverarbeitung | BD24: =IF(DAYS360(PolicenBeginn,PolicenAblauf)>=30*18,"mk-lfv-1:group-4","") | BF24: Trigger | BG24: =IF(DAYS360(PolicenBeginn,PolicenAblauf)<=12*30,Dunkelverarbeitung,Referral) -> Dunkelverarbeitung | BJ24: =IF(DAYS360(PolicenBeginn,PolicenAblauf)>=30*18,"axa_my:group-4","") | BL24: Trigger | BN24: =IF(DAYS360(PolicenBeginn,PolicenAblauf,TRUE)<12*30,"KO Trigger",Dunkelverarbeitung) -> KO Trigger | BP24: =IF(DAYS360(PolicenBeginn,PolicenAblauf)>=30*18,"ergo-lfv-1:group-4","") | BR24: Policenende bzw. Laufzeit | BS24: =BR24 -> Policenende bzw. Laufzeit
A25: Risikofragen | B25: RisikoFragen0c | C25: RisikoFragen | D25: Deckungssumme (1) | F25: =giLimit1 -> 0 | H25: Zahlen | I25: giLimit1 | K25: =RisikoFragen0c -> 0 | M25: Zahlen | N25: RisikoFragen0c | P25: Dunkelverarbeitung | V25: Dunkelverarbeitung | AB25: Dunkelverarbeitung | AH25: Trigger --> siehe Sterne Rechner Angebot | AN25: Dunkelverarbeitung | AT25: Trigger | AZ25: Trigger | BF25: Trigger | BL25: Trigger | BS25: =BR25 -> 0
A26: Risikofragen | B26: RisikoFragen0d | C26: RisikoFragen | D26: Deckungssumme (2) | F26: =giLimit2 -> 0 | H26: Zahlen | I26: giLimit2 | K26: =RisikoFragen0d -> 0 | M26: Zahlen | N26: RisikoFragen0d | P26: Dunkelverarbeitung | V26: Dunkelverarbeitung | AB26: Dunkelverarbeitung | AH26: Trigger --> siehe Sterne Rechner Angebot | AN26: Dunkelverarbeitung | AT26: Trigger | AZ26: Trigger | BF26: Trigger | BL26: Trigger | BS26: =BR26 -> 0
A27: Risikofragen | B27: RisikoFragen0e | C27: RisikoFragen | D27: Deckungssumme (3) | F27: =giLimit3 -> 0 | H27: Zahlen | I27: giLimit3 | K27: =RisikoFragen0e -> 0 | M27: Zahlen | N27: RisikoFragen0e | P27: Dunkelverarbeitung | V27: Dunkelverarbeitung | AB27: Dunkelverarbeitung | AH27: Trigger --> siehe Sterne Rechner Angebot | AN27: Dunkelverarbeitung | AT27: Trigger | AZ27: Trigger | BF27: Trigger | BL27: Trigger | BS27: =BR27 -> 0
A28: Risikofragen | B28: RisikoFragen18 | C28: RisikoFragen | D28: Sind dem Unterzeichner Pflichtverletzungen bekannt, die zu einer Inanspruchnahme der gewünschten Deckung führen können? Wenn ja, bitte Einzelheiten angeben. | H28: yes / no | K28: =IF(L28="YES","ja",IF(L28="NO","nein","")) | M28: yes / no | N28: RisikoFragen18 | P28: Trigger | Q28: =IF(K28=JaAntwort,Referral,Dunkelverarbeitung) -> Dunkelverarbeitung | V28: Trigger | W28: =IF(K28=JaAntwort,Referral,Dunkelverarbeitung) -> Dunkelverarbeitung | AB28: Trigger | AC28: =IF(K28=JaAntwort,Referral,Dunkelverarbeitung) -> Dunkelverarbeitung | AH28: Trigger | AJ28: =IF(K28=JaAntwort,KO_Trigger,Dunkelverarbeitung) -> Dunkelverarbeitung | AN28: Trigger | AO28: =IF(K28=JaAntwort,Referral,Dunkelverarbeitung) -> Dunkelverarbeitung | AT28: Trigger | AU28: =IF(K28=JaAntwort,Referral,Dunkelverarbeitung) -> Dunkelverarbeitung | AZ28: Trigger | BA28: =IF(K28=JaAntwort,Referral,Dunkelverarbeitung) -> Dunkelverarbeitung | BF28: Trigger | BG28: =IF(K28=JaAntwort,Referral,Dunkelverarbeitung) -> Dunkelverarbeitung | BL28: Dunkelverarbeitung | BR28: Dem Unterzeichner sind Pflichtverletzungen bekannt, die zu einer Inanspruchnahme der gewünschten Deckung führen können. | BS28: =BR28 -> Dem Unterzeichner sind Pflichtverletzungen bekannt, die zu einer Inanspruchnahme der gewünschten Deckung führen können.
A29: Risikofragen | B29: RisikoFragen19 | C29: RisikoFragen | D29: Sind in der Vergangenheit Ansprüche gestellt worden, die unter die gewünschte Deckung fallen könnten? Wenn ja, bitte Einzelheiten angeben. | H29: yes / no | K29: =IF(L29="YES","ja",IF(L29="NO","nein","")) | M29: yes / no | N29: RisikoFragen19 | P29: Trigger | Q29: =IF(K29=JaAntwort,Referral,Dunkelverarbeitung) -> Dunkelverarbeitung | V29: Trigger | W29: =IF(K29=JaAntwort,Referral,Dunkelverarbeitung) -> Dunkelverarbeitung | AB29: Trigger | AC29: =IF(K29=JaAntwort,Referral,Dunkelverarbeitung) -> Dunkelverarbeitung | AH29: Trigger | AI29: =IF((AND(K29=JaAntwort,Umsatz>=100000000)),Referral,Dunkelverarbeitung) -> Dunkelverarbeitung | AJ29: =IF(AND(K29=JaAntwort,Umsatz<100000000),KO_Trigger,Dunkelverarbeitung) -> Dunkelverarbeitung | AK29: =IF(AND(K29=JaAntwort,Umsatz>=100000000),0.5,0) -> 0 | AN29: Trigger | AO29: =IF(K29=JaAntwort,Referral,Dunkelverarbeitung) -> Dunkelverarbeitung | AT29: Trigger | AU29: =IF(K29=JaAntwort,Referral,Dunkelverarbeitung) -> Dunkelverarbeitung | AZ29: Trigger | BA29: =IF(K29=JaAntwort,Referral,Dunkelverarbeitung) -> Dunkelverarbeitung | BF29: Trigger | BG29: =IF(K29=JaAntwort,Referral,Dunkelverarbeitung) -> Dunkelverarbeitung | BL29: Trigger | BM29: =IF(K29=JaAntwort,Referral,Dunkelverarbeitung) -> Dunkelverarbeitung | BR29: In der Vergangenheit sind Ansprüche gestellt worden, die unter die gewünschte Deckung fallen könnten. | BS29: =BR29 -> In der Vergangenheit sind Ansprüche gestellt worden, die unter die gewünschte Deckung fallen könnten.
A30: Risikofragen | B30: RisikoFragen20 | C30: RisikoFragen | D30: Wurden in den vergangenen drei Jahren geschäftsführende Organmitglieder im Streit abberufen? Wenn ja, bitte Einzelheiten angeben. | H30: yes / no | K30: =IF(L30="YES","ja",IF(L30="NO","nein","")) | M30: yes / no | N30: RisikoFragen20 | P30: Trigger | Q30: =IF(K30=JaAntwort,Referral,Dunkelverarbeitung) -> Dunkelverarbeitung | V30: Dunkelverarbeitung | AB30: Trigger | AC30: =IF(K30=JaAntwort,Referral,Dunkelverarbeitung) -> Dunkelverarbeitung | AH30: Trigger | AI30: =IF((AND(K30=JaAntwort,Umsatz>=100000000)),Referral,Dunkelverarbeitung) -> Dunkelverarbeitung | AJ30: =IF(AND(K30=JaAntwort,Umsatz<100000000),KO_Trigger,Dunkelverarbeitung) -> Dunkelverarbeitung | AK30: =IF(AND(K30=JaAntwort,Umsatz>=100000000),0.5,0) -> 0 | AN30: Trigger | AO30: =IF(K30=JaAntwort,Referral,Dunkelverarbeitung) -> Dunkelverarbeitung | AT30: Trigger | AU30: =IF(K30=JaAntwort,Referral,Dunkelverarbeitung) -> Dunkelverarbeitung | AZ30: Dunkelverarbeitung | BF30: Dunkelverarbeitung | BH30: =IF(K30=JaAntwort,"KO Trigger",Dunkelverarbeitung) -> Dunkelverarbeitung | BL30: Trigger | BM30: =IF(K30=JaAntwort,Referral,Dunkelverarbeitung) -> Dunkelverarbeitung | BR30: In den vergangenen drei Jahren wurden geschäftsführende Organmitglieder im Streit abberufen. | BS30: =BR30 -> In den vergangenen drei Jahren wurden geschäftsführende Organmitglieder im Streit abberufen.
A31: Risikofragen | B31: RisikoFragen21a | C31: RisikoFragen | D31: Wurde die VN innerhalb der vergangenen drei Jahre neu beherrscht? Wenn ja, bitte Einzelheiten und Datum der Neuberrschung angeben. | H31: yes / no | K31: =IF(L31="YES","ja",IF(L31="NO","nein","")) | M31: yes / no | N31: RisikoFragen21a | P31: Trigger | Q31: =IF(AND(K31=JaAntwort,Vorversicherung=JaAntwort),Referral,Dunkelverarbeitung) -> Dunkelverarbeitung | V31: Trigger | W31: Dunkelverarbeitung | Y31: =IF(Neubeherrschung="ja",0.15,"") | AB31: Trigger | AC31: =IF(K31=JaAntwort,Referral,Dunkelverarbeitung) -> Dunkelverarbeitung | AH31: Dunkelverarbeitung | AK31: =IF(K31=JaAntwort,0.2,0) -> 0 | AN31: Dunkelverarbeitung | AT31: Trigger | AU31: =IF(K31=JaAntwort,Referral,Dunkelverarbeitung) -> Dunkelverarbeitung | AZ31: Dunkelverarbeitung | BF31: Trigger | BG31: =IF(K31=JaAntwort,Referral,Dunkelverarbeitung) -> Dunkelverarbeitung | BL31: Trigger | BM31: =IF(K31=JaAntwort,Referral,Dunkelverarbeitung) -> Dunkelverarbeitung | BR31: Die Versicherungsnehmerin wurde innerhalb der vergangenen drei Jahre neu beherrscht. | BS31: =BR31 -> Die Versicherungsnehmerin wurde innerhalb der vergangenen drei Jahre neu beherrscht.
A32: Risikofragen | B32: RisikoFragen21b | C32: RisikoFragen | D32: Folgefrage: | E32: Ab wann wurde die VN neu beherrscht? | H32: Datum | K32: =RisikoFragen21b -> 0 | M32: Datum | N32: RisikoFragen21b | P32: Dunkelverarbeitung | V32: Dunkelverarbeitung | AB32: Dunkelverarbeitung | AH32: Dunkelverarbeitung | AK32: =IF(TODAY()-365<K32,0.2,"") | AN32: Dunkelverarbeitung | AT32: Trigger | AU32: =IF(K32=JaAntwort,Referral,Dunkelverarbeitung) -> Dunkelverarbeitung | AZ32: Dunkelverarbeitung | BF32: Trigger | BG32: =IF(K32=JaAntwort,Referral,Dunkelverarbeitung) -> Dunkelverarbeitung | BL32: Dunkelverarbeitung | BR32: Neubeherrschung | BS32: =BR32 -> Neubeherrschung
A33: Risikofragen | B33: RisikoFragen22 | C33: RisikoFragen | D33: Wurde innerhalb der vergangenen drei Jahre die Kapitalstruktur der VN geändert? Wenn ja, bitte Einzelheiten angeben. | H33: yes / no | K33: =IF(L33="YES","ja",IF(L33="NO","nein","")) | M33: yes / no | N33: RisikoFragen22 | P33: Trigger | Q33: =IF(K33=JaAntwort,Referral,Dunkelverarbeitung) -> Dunkelverarbeitung | V33: Trigger | W33: =IF(K33=JaAntwort,Referral,Dunkelverarbeitung) -> Dunkelverarbeitung | AB33: Trigger | AC33: =IF(K33=JaAntwort,Referral,Dunkelverarbeitung) -> Dunkelverarbeitung | AH33: Dunkelverarbeitung | AI33: =IF(K33=JaAntwort,Referral,Dunkelverarbeitung) -> Dunkelverarbeitung | AN33: Dunkelverarbeitung | AT33: Trigger | AU33: =IF(K33=JaAntwort,Referral,Dunkelverarbeitung) -> Dunkelverarbeitung | AZ33: Dunkelverarbeitung | BF33: Dunkelverarbeitung | BL33: Trigger | BM33: =IF(K33=JaAntwort,Referral,Dunkelverarbeitung) -> Dunkelverarbeitung | BR33: Innerhalb der vergangenen drei Jahre wurde die Kapitalstruktur der Versicherungsnehmerin geändert. | BS33: =BR33 -> Innerhalb der vergangenen drei Jahre wurde die Kapitalstruktur der Versicherungsnehmerin geändert.
A34: Risikofragen | B34: RisikoFragen23a | C34: RisikoFragen | D34: Besteht oder bestand für zu versichernde Personen bereits eine D&O Deckung im Sinne dieses Fragebogens? | H34: yes / no | K34: =IF(RisikoFragen23a="YES","ja",IF(RisikoFragen23a="NO","nein","")) | M34: yes / no | N34: RisikoFragen23a | P34: Dunkelverarbeitung | V34: Trigger | W34: =IF(K34=JaAntwort,Referral,Dunkelverarbeitung) -> Dunkelverarbeitung | AB34: Dunkelverarbeitung | AH34: Dunkelverarbeitung | AK34: =IF(AND(K34=JaAntwort,DATEDIF(K38,TODAY(),"y")>4),0.1,0) -> 0 | AN34: Dunkelverarbeitung | AT34: Dunkelverarbeitung | AZ34: Dunkelverarbeitung | BF34: Dunkelverarbeitung | BL34: Trigger | BP34: =IF(K34=JaAntwort,"ergo_konti:group-4","") | BR34: Es besteht oder bestand für zu versichernde Personen bereits eine D&O Deckung im Sinne dieses Fragebogens. | BS34: =BR34 -> Es besteht oder bestand für zu versichernde Personen bereits eine D&O Deckung im Sinne dieses Fragebogens.
A35: Risikofragen | B35: RisikoFragen23b | C35: RisikoFragen | D35: Höhe der Versicherungssumme: | E35: Höhe der Versicherungssumme: | H35: Text | K35: =RisikoFragen23b -> 0 | M35: Text | N35: RisikoFragen23b | P35: Dunkelverarbeitung | V35: Dunkelverarbeitung | AB35: Dunkelverarbeitung | AH35: Dunkelverarbeitung | AN35: Dunkelverarbeitung | AT35: Trigger | AU35: =IF(K35 > 7500000,Referral,Dunkelverarbeitung) -> Dunkelverarbeitung | AZ35: Trigger | BF35: Dunkelverarbeitung | BL35: Dunkelverarbeitung | BM35: =IF(K35<=5000000,Dunkelverarbeitung,Referral) -> Dunkelverarbeitung | BR35: Höhe der Versicherungssumme der Vorversicherung | BS35: =BR35 -> Höhe der Versicherungssumme der Vorversicherung
A36: Risikofragen | B36: RisikoFragen23c | C36: RisikoFragen | D36: Vorschäden? (Sind für den Vorvertrag Umstandsmeldungen oder Schäden gemeldet worden?) | E36: Vorschäden? | H36: Text | K36: =IF(L36="YES","ja",IF(L36="NO","nein","")) | M36: Text | N36: RisikoFragen23c | P36: Trigger | Q36: =IF(K36=JaAntwort,Referral,Dunkelverarbeitung) -> Dunkelverarbeitung | V36: Dunkelverarbeitung | AB36: Trigger | AC36: =IF(K36=JaAntwort,Referral,Dunkelverarbeitung) -> Dunkelverarbeitung | AH36: Trigger | AI36: =IF(K36=JaAntwort,Referral,Dunkelverarbeitung) -> Dunkelverarbeitung | AK36: =IF(K36=JaAntwort,0.1,0) -> 0 | AN36: Trigger | AO36: =IF(K36=JaAntwort,Referral,Dunkelverarbeitung) -> Dunkelverarbeitung | AT36: Trigger | AU36: =IF(K36=JaAntwort,Referral,Dunkelverarbeitung) -> Dunkelverarbeitung | AZ36: Trigger | BA36: =IF($K36=JaAntwort,Referral,Dunkelverarbeitung) -> Dunkelverarbeitung | BF36: Trigger | BH36: =IF(K36=JaAntwort,"KO Trigger",Dunkelverarbeitung) -> Dunkelverarbeitung | BL36: Trigger | BM36: =IF(K36=JaAntwort,Referral,Dunkelverarbeitung) -> Dunkelverarbeitung | BR36: Vorschäden | BS36: =BR36 -> Vorschäden
A37: Risikofragen | B37: RisikoFragen23d | C37: RisikoFragen | D37: Versicherungsscheinnummer: | E37: Versicherungsscheinnummer: | H37: Text | K37: =IF(L37="YES","ja",IF(L37="NO","nein","")) | M37: Text | N37: RisikoFragen23d | P37: Dunkelverarbeitung | V37: Dunkelverarbeitung | AB37: Dunkelverarbeitung | AH37: Dunkelverarbeitung | AN37: Dunkelverarbeitung | AT37: Dunkelverarbeitung | AZ37: Trigger | BF37: Dunkelverarbeitung | BL37: Dunkelverarbeitung | BS37: =BR37 -> 0
A38: Risikofragen | B38: RisikoFragen23e | C38: RisikoFragen | D38: Kontinuitätsdatum (Beginn Vorvertrag) | E38: Kontinuitätsdatum: | H38: Datum | K38: =RisikoFragen23e -> 0 | M38: Datum | N38: RisikoFragen23e | P38: Dunkelverarbeitung | V38: Dunkelverarbeitung | AB38: Dunkelverarbeitung | AH38: Dunkelverarbeitung | AN38: Dunkelverarbeitung | AT38: Dunkelverarbeitung | AZ38: Trigger | BF38: Dunkelverarbeitung | BL38: Dunkelverarbeitung | BR38: Kontinuität von mehr als 5 Jahre angefragt | BS38: =BR38 -> Kontinuität von mehr als 5 Jahre angefragt
A39: Risikofragen | B39: RisikoFragenVorvertragExtendedReportingPeriod | C39: RisikoFragen | D39: Gewährt der Vorversicherer eine unverfallbare Nachmeldefrist von mindestens 24 Monaten? | E39: Gewährt der Vorversicherer eine unverfallbare Nachmeldefrist von mindestens 24 Monaten? | H39: yes / no | K39: =IF(RisikoFragenVorvertragExtendedReportingPeriod="YES","ja",IF(RisikoFragenVorvertragExtendedReportingPeriod="NO","nein",IF(RisikoFragenVorvertragExtendedReportingPeriod="UNKNOWN","unbekannt",""))) | M39: yes / no | N39: RisikoFragenVorvertragExtendedReportingPeriod | P39: Trigger | Q39: =IF(OR(K39=NeinAntwort, K39="unbekannt"),Referral,Dunkelverarbeitung) -> Dunkelverarbeitung | V39: Dunkelverarbeitung | AB39: Trigger | AC39: =IF(OR(K39=NeinAntwort, K39="unbekannt"),Referral,Dunkelverarbeitung) -> Dunkelverarbeitung | AH39: Trigger | AI39: =IF(K39="unbekannt",Referral,Dunkelverarbeitung) -> Dunkelverarbeitung | AN39: Trigger | AO39: =IF(OR(K39=NeinAntwort, K39="unbekannt"),Referral,Dunkelverarbeitung) -> Dunkelverarbeitung | AT39: Trigger | AU39: =IF(OR(K39=NeinAntwort, K39="unbekannt"),Referral,Dunkelverarbeitung) -> Dunkelverarbeitung | AZ39: Trigger | BA39: =IF(OR(K39=NeinAntwort, K39="unbekannt"),Referral,Dunkelverarbeitung) -> Dunkelverarbeitung | BF39: Dunkelverarbeitung | BL39: Trigger | BM39: =IF(OR(K39=NeinAntwort, K39="unbekannt"),Referral,Dunkelverarbeitung) -> Dunkelverarbeitung | BR39: Der Vorversicherer gewährt keine unverfallbare Nachmeldefrist von mindestens 24 Monaten. | BS39: =BR39 -> Der Vorversicherer gewährt keine unverfallbare Nachmeldefrist von mindestens 24 Monaten.
A40: Risikofragen | B40: RisikoFragenVorvertragNoGapsInCoverage | C40: RisikoFragen | D40: Schließt der angefragte Vertrag ohne zeitliche Unterbrechung an den Vorvertrag an? | E40: Schließt der angefragte Vertrag ohne zeitliche Unterbrechung an den Vorvertrag an? | H40: yes / no | K40: =IF(RisikoFragenVorvertragNoGapsInCoverage="YES","ja",IF(RisikoFragenVorvertragNoGapsInCoverage="NO","nein","")) | M40: yes / no | N40: RisikoFragenVorvertragNoGapsInCoverage | P40: Trigger | Q40: =IF(K40=NeinAntwort,Referral,Dunkelverarbeitung) -> Dunkelverarbeitung | V40: Dunkelverarbeitung | AB40: Trigger | AC40: =IF(K40=NeinAntwort,Referral,Dunkelverarbeitung) -> Dunkelverarbeitung | AE40: =IF(AND(RisikoFragen23a="YES",K40=JaAntwort),15%,"") | AH40: Dunkelverarbeitung | AN40: Trigger | AO40: =IF(K40=NeinAntwort,Referral,Dunkelverarbeitung) -> Dunkelverarbeitung | AT40: Trigger | AU40: =IF(K40=NeinAntwort,Referral,Dunkelverarbeitung) -> Dunkelverarbeitung | AZ40: Trigger | BF40: Dunkelverarbeitung | BL40: Dunkelverarbeitung | BR40: Der angefragte Vertrag schließt nicht ohne zeitliche Unterbrechung an den Vorvertrag an. | BS40: =BR40 -> Der angefragte Vertrag schließt nicht ohne zeitliche Unterbrechung an den Vorvertrag an.
...

Sheet Daten-Abzug
I1: Grobindikation Light DS
D2: Angebot | I2: Sterne | J2: DS 1 | K2: DS 2 | L2: DS 3
D3: DS 1 | E3: DS 2 | F3: DS 3 | I3: Versicherer | J3: =IFERROR('Sterne-Rechner - GI'!V39,"") -> Kein Angebot möglich! | K3: =IFERROR('Sterne-Rechner - GI'!V40,"") -> Kein Angebot möglich! | L3: =IFERROR('Sterne-Rechner - GI'!V41,"") -> Kein Angebot möglich!
C4: Angefragte Deckungssumme | D4: =Deckungssumme1 -> 0 | E4: =Deckungssumme2 -> 0 | F4: =Deckungssumme3 -> 0 | I4: Preis | J4: =IFERROR(ROUND('Sterne-Rechner - GI'!X39,2),"") | K4: =IFERROR(ROUND('Sterne-Rechner - GI'!X40,2),"") | L4: =IFERROR(ROUND('Sterne-Rechner - GI'!X41,2),"")
B5: WVAG | C5: Sterne | D5: =TEXT('Sterne-Rechner - Angebot'!Y4,"0") | E5: =TEXT('Sterne-Rechner - Angebot'!Y5,"0") | F5: =TEXT('Sterne-Rechner - Angebot'!Y6,"0") | I5: Angebotene Deckungssumme | J5: =IFERROR(ROUND('Sterne-Rechner - GI'!W39,0),"") | K5: =IFERROR(ROUND('Sterne-Rechner - GI'!W40,0),"") | L5: =IFERROR(ROUND('Sterne-Rechner - GI'!W41,0),"")
C6: Bewertungsfaktor | D6: ='Sterne-Rechner - Angebot'!Q4 -> 75 | E6: ='Sterne-Rechner - Angebot'!Q5 -> 75 | F6: ='Sterne-Rechner - Angebot'!Q6 -> 75
C7: Angebotene Deckungssumme | D7: ='Sterne-Rechner - Angebot'!AD4 -> 0 | E7: ='Sterne-Rechner - Angebot'!AD5 -> 0 | F7: ='Sterne-Rechner - Angebot'!AD6 -> 0
C8: Nettoisierte Jahresnettoprämie | D8: ='Sterne-Rechner - Angebot'!AC4 | E8: ='Sterne-Rechner - Angebot'!AC5 | F8: ='Sterne-Rechner - Angebot'!AC6
C9: Provision Howden | D9: ='Preisrechner Alle Tarife'!R34 -> 0 | E9: ='Preisrechner Alle Tarife'!S34 -> 0 | F9: ='Preisrechner Alle Tarife'!T34 -> 0
C10: Provision Coop-Makler | D10: ='Preisrechner Alle Tarife'!V34 -> 0 | E10: ='Preisrechner Alle Tarife'!W34 -> 0 | F10: ='Preisrechner Alle Tarife'!X34 -> 0
C11: Zusätzliche gewählte Deckungsoptionen
C12: Klauseln | D12: =wvagUsedClauses -> , | E12: =wvagUsedClauses -> , | F12: =wvagUsedClauses -> ,
C13: Status | D13: ='Sterne-Rechner - Angebot'!AE4 -> OFFER_DECLINED | E13: ='Sterne-Rechner - Angebot'!AE5 -> OFFER_DECLINED | F13: ='Sterne-Rechner - Angebot'!AE6 -> OFFER_DECLINED
C14: Axa Facility (wahr) / Axa MMC (falsch) | D14: =IF(AXAFacilityKriterien="Kriterien erfüllt",TRUE,FALSE) -> FALSE
B15: AXA | C15: Sterne | D15: =TEXT('Sterne-Rechner - Angebot'!Y7,"0") | E15: =TEXT('Sterne-Rechner - Angebot'!Y8,"0") | F15: =TEXT('Sterne-Rechner - Angebot'!Y9,"0")
C16: Bewertungsfaktor | D16: ='Sterne-Rechner - Angebot'!Q7 -> 95 | E16: ='Sterne-Rechner - Angebot'!Q8 -> 95 | F16: ='Sterne-Rechner - Angebot'!Q9 -> 95
C17: Angebotene Deckungssumme | D17: ='Sterne-Rechner - Angebot'!AD7 -> 0 | E17: ='Sterne-Rechner - Angebot'!AD8 -> 0 | F17: ='Sterne-Rechner - Angebot'!AD9 -> 0
C18: Nettoisierte Jahresnettoprämie | D18: ='Sterne-Rechner - Angebot'!AC7 | E18: ='Sterne-Rechner - Angebot'!AC8 | F18: ='Sterne-Rechner - Angebot'!AC9
C19: Provision Howden | D19: ='Preisrechner Alle Tarife'!R35 -> 0 | E19: ='Preisrechner Alle Tarife'!S35 -> 0 | F19: ='Preisrechner Alle Tarife'!T35 -> 0
C20: Provision Coop-Makler | D20: ='Preisrechner Alle Tarife'!V35 -> 0 | E20: ='Preisrechner Alle Tarife'!W35 -> 0 | F20: ='Preisrechner Alle Tarife'!X35 -> 0
C21: Zusätzliche gewählte Deckungsoptionen | D21: =IF(AND(OR(Fragenkatalog!K8="AG",Fragenkatalog!K8="SE",Fragenkatalog!K8="Versicherungsverein aG",Fragenkatalog!K8="e.G."),Außenumsatz>150000000,Branche="FI"),"WpHG,","") | E21: =IF(AND(OR(Fragenkatalog!K8="AG",Fragenkatalog!K8="SE",Fragenkatalog!K8="Versicherungsverein aG",Fragenkatalog!K8="e.G."),Außenumsatz>150000000,Branche="FI"),"WpHG,","") | F21: =IF(AND(OR(Fragenkatalog!K8="AG",Fragenkatalog!K8="SE",Fragenkatalog!K8="Versicherungsverein aG",Fragenkatalog!K8="e.G."),Außenumsatz>150000000,Branche="FI"),"WpHG,","")
C22: Klauseln | D22: =axaUsedClauses -> ,, | E22: =axaUsedClauses -> ,, | F22: =axaUsedClauses -> ,,
C23: Status | D23: ='Sterne-Rechner - Angebot'!AE7 -> OFFER_DECLINED | E23: ='Sterne-Rechner - Angebot'!AE8 -> OFFER_DECLINED | F23: ='Sterne-Rechner - Angebot'!AE9 -> OFFER_DECLINED
B24: =IF('Sterne-Rechner - Angebot'!C13=OfferReady,"AIG Facility","AIG") -> AIG | C24: Facility ja / nein | D24: =IF(AIGFacilityKriterien="Kriterien erfüllt",TRUE,FALSE) -> FALSE
C25: Sterne | D25: =TEXT(IF(D24=TRUE,'Sterne-Rechner - Angebot'!Y13,'Sterne-Rechner - Angebot'!Y10),"0") | E25: =TEXT(IF(D24=TRUE,'Sterne-Rechner - Angebot'!Y14,'Sterne-Rechner - Angebot'!Y11),"0") | F25: =TEXT(IF(D24=TRUE,'Sterne-Rechner - Angebot'!Y15,'Sterne-Rechner - Angebot'!Y12),"0")
C26: Bewertungsfaktor | D26: 0 | E26: 0 | F26: 0
C27: Angebotene Deckungssumme | D27: =IF(aigFacilityYesNo=TRUE,'Sterne-Rechner - Angebot'!AD13,'Sterne-Rechner - Angebot'!AD10) -> 0 | E27: =IF(aigFacilityYesNo=TRUE,'Sterne-Rechner - Angebot'!AD14,'Sterne-Rechner - Angebot'!AD11) -> 0 | F27: =IF(aigFacilityYesNo=TRUE,'Sterne-Rechner - Angebot'!AD15,'Sterne-Rechner - Angebot'!AD12) -> 0
C28: Nettoisierte Jahresnettoprämie | D28: =IF(aigFacilityYesNo=TRUE,'Sterne-Rechner - Angebot'!AC13,'Sterne-Rechner - Angebot'!AC10) | E28: =IF(aigFacilityYesNo=TRUE,'Sterne-Rechner - Angebot'!AC14,'Sterne-Rechner - Angebot'!AC11) | F28: =IF(aigFacilityYesNo=TRUE,'Sterne-Rechner - Angebot'!AC15,'Sterne-Rechner - Angebot'!AC12)
C29: Provision Howden | D29: =IF(aigFacilityYesNo=TRUE,'Preisrechner Alle Tarife'!U8,'Preisrechner Alle Tarife'!U7) -> 0 | E29: =IF(aigFacilityYesNo=TRUE,'Preisrechner Alle Tarife'!V8,'Preisrechner Alle Tarife'!V7) -> 0 | F29: =IF(aigFacilityYesNo=TRUE,'Preisrechner Alle Tarife'!W8,'Preisrechner Alle Tarife'!W7) -> 0
C30: Provision Coop-Makler | D30: =IF(aigFacilityYesNo=TRUE,'Preisrechner Alle Tarife'!Y8,'Preisrechner Alle Tarife'!Y7) -> 0
C31: Zusätzliche gewählte Deckungsoptionen
C32: Klauseln | D32: =aigUsedClauses -> , | E32: =aigUsedClauses -> , | F32: =aigUsedClauses -> ,
C33: Status | D33: =IF(aigFacilityYesNo=TRUE,'Sterne-Rechner - Angebot'!AE13,'Sterne-Rechner - Angebot'!AE10) -> OFFER_DECLINED | E33: =IF(aigFacilityYesNo=TRUE,'Sterne-Rechner - Angebot'!AE14,'Sterne-Rechner - Angebot'!AE11) -> OFFER_DECLINED | F33: =IF(aigFacilityYesNo=TRUE,'Sterne-Rechner - Angebot'!AE15,'Sterne-Rechner - Angebot'!AE12) -> OFFER_DECLINED
B34: DUAL | C34: Sterne | D34: =TEXT('Sterne-Rechner - Angebot'!Y16,"0") | E34: =TEXT('Sterne-Rechner - Angebot'!Y17,"0") | F34: =TEXT('Sterne-Rechner - Angebot'!Y18,"0")
C35: Bewertungsfaktor | D35: ='Sterne-Rechner - Angebot'!Q16 -> 10 | E35: ='Sterne-Rechner - Angebot'!Q17 -> 10 | F35: ='Sterne-Rechner - Angebot'!Q18 -> 10
C36: Angebotene Deckungssumme | D36: ='Sterne-Rechner - Angebot'!AD16 -> 0 | E36: ='Sterne-Rechner - Angebot'!AD17 -> 0 | F36: ='Sterne-Rechner - Angebot'!AD18 -> 0
C37: Nettoisierte Jahresnettoprämie | D37: ='Sterne-Rechner - Angebot'!AC16 | E37: ='Sterne-Rechner - Angebot'!AC17 | F37: ='Sterne-Rechner - Angebot'!AC18
C38: Provision Howden | D38: ='Preisrechner Alle Tarife'!R38 -> 0 | E38: ='Preisrechner Alle Tarife'!S38 -> 0 | F38: ='Preisrechner Alle Tarife'!T38 -> 0
C39: Provision Coop-Makler | D39: ='Preisrechner Alle Tarife'!V38 -> 0 | E39: ='Preisrechner Alle Tarife'!W38 -> 0 | F39: ='Preisrechner Alle Tarife'!X38 -> 0
C40: Zusätzliche gewählte Deckungsoptionen
...

Sheet Deckungsoptionen
A1: Deckungsoptionen Defaults:
A3: Diese Werte sind Default-Werte. Hier keine Berechnungen mit anderen Felder ausführen!
A5: Zweifachmaximierung | B5: AIG | C5: AXA XL - Facility | D5: AXA XL - MMC | E5: DUAL | F5: Newline | G5: Berkley | H5: WVAG | I5: Markel | J5: Liberty | K5: Ergo
A6: Option gewählt | B6: TRUE | C6: TRUE | D6: TRUE | E6: TRUE | F6: TRUE | G6: TRUE | H6: TRUE | I6: TRUE | J6: TRUE | K6: TRUE
A7: Prämienneutral | B7: FALSE | C7: FALSE | D7: FALSE | E7: FALSE | F7: FALSE | G7: FALSE | H7: FALSE | I7: FALSE | J7: FALSE | K7: FALSE
A8: Prozentsatz | B8: 15 | C8: 20 | D8: 20 | E8: 25 | F8: 15 | G8: 15 | H8: 15 | I8: 10 | J8: 20 | K8: 20
A10: Schiedsgericht (ARIAS) | B10: AIG | C10: AXA XL - Facility | D10: AXA XL - MMC | E10: DUAL | F10: Newline | G10: Berkley | H10: WVAG | I10: Markel | J10: Liberty | K10: Ergo | M10: ARIAS Included | N10: Manche neue Bedingungswerke haben die Schiedsgerichtklausel immer mit drin (Liberty,Axa MMC ab 2024, Ergo ab 2024, Newline ab 2024). Option muss immer Prämienneutral angewählt sein
A11: Option gewählt | B11: TRUE | C11: TRUE | D11: =includedArbitrationCourtSelected -> TRUE | E11: =noOptionSelected -> FALSE | F11: =includedArbitrationCourtSelected -> TRUE | G11: =noOptionSelected -> FALSE | H11: =noOptionSelected -> FALSE | I11: =includedArbitrationCourtSelected -> TRUE | J11: =includedArbitrationCourtSelected -> TRUE | K11: =includedArbitrationCourtSelected -> TRUE | M11: TRUE
A12: Prämienneutral | B12: FALSE | C12: TRUE | D12: =includedArbitrationCourtPremiumNeutral -> TRUE | E12: =noOptionPremiumNeutral -> FALSE | F12: =includedArbitrationCourtPremiumNeutral -> TRUE | G12: =noOptionPremiumNeutral -> FALSE | H12: =noOptionPremiumNeutral -> FALSE | I12: =includedArbitrationCourtPremiumNeutral -> TRUE | J12: =includedArbitrationCourtPremiumNeutral -> TRUE | K12: =includedArbitrationCourtPremiumNeutral -> TRUE | M12: TRUE
A13: Prozentsatz | B13: 20 | C13: 0 | D13: =includedArbitrationCourtPercentage -> 0 | E13: =noOptionPercentage -> 0 | F13: =includedArbitrationCourtPercentage -> 0 | G13: =noOptionPercentage -> 0 | H13: =noOptionPercentage -> 0 | I13: =includedArbitrationCourtPercentage -> 0 | J13: =includedArbitrationCourtPercentage -> 0 | K13: =includedArbitrationCourtPercentage -> 0 | M13: 0
A15: WpHG | B15: AIG | C15: AXA XL - Facility | D15: AXA XL - MMC | E15: DUAL | F15: Newline | G15: Berkley | H15: WVAG | I15: Markel | J15: Liberty | K15: Ergo
A16: Option gewählt | B16: TRUE | C16: FALSE | D16: =noOptionSelected -> FALSE | E16: =noOptionSelected -> FALSE | F16: FALSE | G16: FALSE | H16: =noOptionSelected -> FALSE | I16: FALSE | J16: =noOptionSelected -> FALSE | K16: =noOptionSelected -> FALSE
A17: Prämienneutral | B17: FALSE | C17: FALSE | D17: =noOptionPremiumNeutral -> FALSE | E17: =noOptionPremiumNeutral -> FALSE | F17: FALSE | G17: FALSE | H17: =noOptionPremiumNeutral -> FALSE | I17: FALSE | J17: =noOptionPremiumNeutral -> FALSE | K17: =noOptionPremiumNeutral -> FALSE
A18: Prozentsatz | B18: 10 | C18: 10 | D18: =noOptionPercentage -> 0 | E18: =noOptionPercentage -> 0 | F18: 10 | G18: 10 | H18: =noOptionPercentage -> 0 | I18: 10 | J18: =noOptionPercentage -> 0 | K18: =noOptionPercentage -> 0
A20: Format zeigt, dass Versicherer | B20: FALSE
A21: die Option nicht anbietet | B21: FALSE
B22: 0

Sheet Referral Stati
B1: AGCS | D1: Württembergische | F1: AXA Facility | H1: AIG | J1: AIG Facility | L1: DUAL | N1: Newline | P1: Berkley | R1: Markel | T1: Liberty | V1: ERGO
A2: Trigger | B2: Referral | C2: KO | D2: Referral | E2: KO | F2: Referral | G2: KO | H2: Referral | I2: KO | J2: Referral | K2: KO | L2: Referral | M2: KO | N2: Referral | O2: KO | P2: Referral | Q2: KO | R2: Referral | S2: KO | T2: Referral | U2: KO | V2: Referral | W2: KO
A3: 1 | B3: {=IFERROR(IF(ROW(A1)>COUNTA(B$20:B$162),"",INDEX(B:B,SMALL(IF(B$20:B$162<>"", ROW($20:$162)),ROW(A1)))),"")} | C3: {=IFERROR(IF(ROW(A1)>COUNTA(C$20:C$162),"",INDEX(C:C,SMALL(IF(C$20:C$162<>"", ROW($20:$162)),ROW(A1)))),"")} | D3: {=IFERROR(INDEX(D:D,SMALL(IF(D$20:D$177<>"", ROW($20:$177)),$A3)),"")} -> Eigenkapital | E3: {=IFERROR(INDEX(E:E,SMALL(IF(E$20:E$177<>"", ROW($20:$177)),$A3)),"")} | F3: {=IFERROR(INDEX(F:F,SMALL(IF(F$20:F$177<>"", ROW($20:$177)),$A3)),"")} -> Policenbeginn | G3: {=IFERROR(INDEX(G:G,SMALL(IF(G$20:G$177<>"", ROW($20:$177)),$A3)),"")} -> Policenende bzw. Laufzeit | H3: {=IFERROR(IF(ROW(D1)>COUNTA(H$20:H$162),"",INDEX(H:H,SMALL(IF(H$20:H$162<>"", ROW($20:$162)),ROW($A$1)))),"")} | I3: {=IFERROR(IF(ROW(E1)>COUNTA(I$20:I$162),"",INDEX(I:I,SMALL(IF(I$20:I$162<>"", ROW($20:$162)),ROW($A$1)))),"")} | J3: {=IFERROR(IF(ROW(F1)>COUNTA(J$20:J$162),"",INDEX(J:J,SMALL(IF(J$20:J$162<>"", ROW($20:$162)),ROW($A$1)))),"")} -> Policenbeginn | K3: {=IFERROR(IF(ROW(G1)>COUNTA(K$20:K$162),"",INDEX(K:K,SMALL(IF(K$20:K$162<>"", ROW($20:$162)),ROW($A$1)))),"")} | L3: {=IFERROR(INDEX(L:L,SMALL(IF(L$20:L$177<>"", ROW($20:$177)),$A3)),"")} -> Policenbeginn | M3: {=IFERROR(INDEX(M:M,SMALL(IF(M$20:M$177<>"", ROW($20:$177)),$A3)),"")} -> Manueller Backstop | N3: {=IFERROR(INDEX(N:N,SMALL(IF(N$20:N$177<>"", ROW($20:$177)),$A3)),"")} -> Policenbeginn | O3: {=IFERROR(INDEX(O:O,SMALL(IF(O$20:O$177<>"", ROW($20:$177)),$A3)),"")} | P3: {=IFERROR(INDEX(P:P,SMALL(IF(P$20:P$177<>"", ROW($20:$177)),$A3)),"")} -> Policenbeginn | Q3: {=IFERROR(INDEX(Q:Q,SMALL(IF(Q$20:Q$177<>"", ROW($20:$177)),$A3)),"")} | R3: {=IFERROR(INDEX(R:R,SMALL(IF(R$20:R$177<>"", ROW($20:$177)),$A3)),"")} | S3: {=IFERROR(INDEX(S:S,SMALL(IF(S$20:S$177<>"", ROW($20:$177)),$A3)),"")} -> Policenbeginn | T3: {=IFERROR(INDEX(T:T,SMALL(IF(T$20:T$177<>"", ROW($20:$177)),$A3)),"")} | U3: {=IFERROR(INDEX(U:U,SMALL(IF(U$20:U$177<>"", ROW($20:$177)),$A3)),"")} | V3: {=IFERROR(INDEX(V:V,SMALL(IF(V$20:V$177<>"", ROW($20:$177)),$A3)),"")} -> Nettoisierung | W3: {=IFERROR(INDEX(W:W,SMALL(IF(W$20:W$177<>"", ROW($20:$177)),$A3)),"")} -> Policenende bzw. Laufzeit
A4: =A3+1 -> 2 | B4: {=IFERROR(IF(ROW(A2)>COUNTA(B$20:B$162),"",INDEX(B:B,SMALL(IF(B$20:B$162<>"", ROW($20:$162)),ROW(A2)))),"")} | C4: {=IFERROR(IF(ROW(A2)>COUNTA(C$20:C$162),"",INDEX(C:C,SMALL(IF(C$20:C$162<>"", ROW($20:$162)),ROW(A2)))),"")} | D4: {=IFERROR(INDEX(D:D,SMALL(IF(D$20:D$177<>"", ROW($20:$177)),$A4)),"")} | E4: {=IFERROR(INDEX(E:E,SMALL(IF(E$20:E$177<>"", ROW($20:$177)),$A4)),"")} | F4: {=IFERROR(INDEX(F:F,SMALL(IF(F$20:F$177<>"", ROW($20:$177)),$A4)),"")} -> Nettoisierung | G4: {=IFERROR(INDEX(G:G,SMALL(IF(G$20:G$177<>"", ROW($20:$177)),$A4)),"")} | H4: {=IFERROR(IF(ROW(D2)>COUNTA(H$20:H$162),"",INDEX(H:H,SMALL(IF(H$20:H$162<>"", ROW($20:$162)),ROW(C2)))),"")} | I4: {=IFERROR(IF(ROW(E2)>COUNTA(I$20:I$162),"",INDEX(I:I,SMALL(IF(I$20:I$162<>"", ROW($20:$162)),ROW(D2)))),"")} | J4: {=IFERROR(IF(ROW(F2)>COUNTA(J$20:J$162),"",INDEX(J:J,SMALL(IF(J$20:J$162<>"", ROW($20:$162)),ROW(E2)))),"")} | K4: {=IFERROR(IF(ROW(G2)>COUNTA(K$20:K$162),"",INDEX(K:K,SMALL(IF(K$20:K$162<>"", ROW($20:$162)),ROW(F2)))),"")} | L4: {=IFERROR(INDEX(L:L,SMALL(IF(L$20:L$177<>"", ROW($20:$177)),$A4)),"")} | M4: {=IFERROR(INDEX(M:M,SMALL(IF(M$20:M$177<>"", ROW($20:$177)),$A4)),"")} | N4: {=IFERROR(INDEX(N:N,SMALL(IF(N$20:N$177<>"", ROW($20:$177)),$A4)),"")} -> Policenende bzw. Laufzeit | O4: {=IFERROR(INDEX(O:O,SMALL(IF(O$20:O$177<>"", ROW($20:$177)),$A4)),"")} | P4: {=IFERROR(INDEX(P:P,SMALL(IF(P$20:P$177<>"", ROW($20:$177)),$A4)),"")} -> Policenende bzw. Laufzeit | Q4: {=IFERROR(INDEX(Q:Q,SMALL(IF(Q$20:Q$177<>"", ROW($20:$177)),$A4)),"")} | R4: {=IFERROR(INDEX(R:R,SMALL(IF(R$20:R$177<>"", ROW($20:$177)),$A4)),"")} | S4: {=IFERROR(INDEX(S:S,SMALL(IF(S$20:S$177<>"", ROW($20:$177)),$A4)),"")} | T4: {=IFERROR(INDEX(T:T,SMALL(IF(T$20:T$177<>"", ROW($20:$177)),$A4)),"")} | U4: {=IFERROR(INDEX(U:U,SMALL(IF(U$20:U$177<>"", ROW($20:$177)),$A4)),"")} | V4: {=IFERROR(INDEX(V:V,SMALL(IF(V$20:V$177<>"", ROW($20:$177)),$A4)),"")} | W4: {=IFERROR(INDEX(W:W,SMALL(IF(W$20:W$177<>"", ROW($20:$177)),$A4)),"")}
A5: =A4+1 -> 3 | B5: {=IFERROR(IF(ROW(A3)>COUNTA(B$20:B$162),"",INDEX(B:B,SMALL(IF(B$20:B$162<>"", ROW($20:$162)),ROW(A3)))),"")} | C5: {=IFERROR(IF(ROW(A3)>COUNTA(C$20:C$162),"",INDEX(C:C,SMALL(IF(C$20:C$162<>"", ROW($20:$162)),ROW(A3)))),"")} | D5: {=IFERROR(INDEX(D:D,SMALL(IF(D$20:D$177<>"", ROW($20:$177)),$A5)),"")} | E5: {=IFERROR(INDEX(E:E,SMALL(IF(E$20:E$177<>"", ROW($20:$177)),$A5)),"")} | F5: {=IFERROR(INDEX(F:F,SMALL(IF(F$20:F$177<>"", ROW($20:$177)),$A5)),"")} | G5: {=IFERROR(INDEX(G:G,SMALL(IF(G$20:G$177<>"", ROW($20:$177)),$A5)),"")} | H5: {=IFERROR(IF(ROW(D3)>COUNTA(H$20:H$162),"",INDEX(H:H,SMALL(IF(H$20:H$162<>"", ROW($20:$162)),ROW(C3)))),"")} | I5: {=IFERROR(IF(ROW(E3)>COUNTA(I$20:I$162),"",INDEX(I:I,SMALL(IF(I$20:I$162<>"", ROW($20:$162)),ROW(D3)))),"")} | J5: {=IFERROR(IF(ROW(F3)>COUNTA(J$20:J$162),"",INDEX(J:J,SMALL(IF(J$20:J$162<>"", ROW($20:$162)),ROW(E3)))),"")} | K5: {=IFERROR(IF(ROW(G3)>COUNTA(K$20:K$162),"",INDEX(K:K,SMALL(IF(K$20:K$162<>"", ROW($20:$162)),ROW(F3)))),"")} | L5: {=IFERROR(INDEX(L:L,SMALL(IF(L$20:L$177<>"", ROW($20:$177)),$A5)),"")} | M5: {=IFERROR(INDEX(M:M,SMALL(IF(M$20:M$177<>"", ROW($20:$177)),$A5)),"")} | N5: {=IFERROR(INDEX(N:N,SMALL(IF(N$20:N$177<>"", ROW($20:$177)),$A5)),"")} -> Nettoisierung | O5: {=IFERROR(INDEX(O:O,SMALL(IF(O$20:O$177<>"", ROW($20:$177)),$A5)),"")} | P5: {=IFERROR(INDEX(P:P,SMALL(IF(P$20:P$177<>"", ROW($20:$177)),$A5)),"")} | Q5: {=IFERROR(INDEX(Q:Q,SMALL(IF(Q$20:Q$177<>"", ROW($20:$177)),$A5)),"")} | R5: {=IFERROR(INDEX(R:R,SMALL(IF(R$20:R$177<>"", ROW($20:$177)),$A5)),"")} | S5: {=IFERROR(INDEX(S:S,SMALL(IF(S$20:S$177<>"", ROW($20:$177)),$A5)),"")} | T5: {=IFERROR(INDEX(T:T,SMALL(IF(T$20:T$177<>"", ROW($20:$177)),$A5)),"")} | U5: {=IFERROR(INDEX(U:U,SMALL(IF(U$20:U$177<>"", ROW($20:$177)),$A5)),"")} | V5: {=IFERROR(INDEX(V:V,SMALL(IF(V$20:V$177<>"", ROW($20:$177)),$A5)),"")} | W5: {=IFERROR(INDEX(W:W,SMALL(IF(W$20:W$177<>"", ROW($20:$177)),$A5)),"")}
A6: =A5+1 -> 4 | B6: {=IFERROR(IF(ROW(A4)>COUNTA(B$20:B$162),"",INDEX(B:B,SMALL(IF(B$20:B$162<>"", ROW($20:$162)),ROW(A4)))),"")} | C6: {=IFERROR(IF(ROW(A4)>COUNTA(C$20:C$162),"",INDEX(C:C,SMALL(IF(C$20:C$162<>"", ROW($20:$162)),ROW(A4)))),"")} | D6: {=IFERROR(INDEX(D:D,SMALL(IF(D$20:D$177<>"", ROW($20:$177)),$A6)),"")} | E6: {=IFERROR(INDEX(E:E,SMALL(IF(E$20:E$177<>"", ROW($20:$177)),$A6)),"")} | F6: {=IFERROR(INDEX(F:F,SMALL(IF(F$20:F$177<>"", ROW($20:$177)),$A6)),"")} | G6: {=IFERROR(INDEX(G:G,SMALL(IF(G$20:G$177<>"", ROW($20:$177)),$A6)),"")} | H6: {=IFERROR(IF(ROW(D4)>COUNTA(H$20:H$162),"",INDEX(H:H,SMALL(IF(H$20:H$162<>"", ROW($20:$162)),ROW(C4)))),"")} | I6: {=IFERROR(IF(ROW(E4)>COUNTA(I$20:I$162),"",INDEX(I:I,SMALL(IF(I$20:I$162<>"", ROW($20:$162)),ROW(D4)))),"")} | J6: {=IFERROR(IF(ROW(F4)>COUNTA(J$20:J$162),"",INDEX(J:J,SMALL(IF(J$20:J$162<>"", ROW($20:$162)),ROW(E4)))),"")} | K6: {=IFERROR(IF(ROW(G4)>COUNTA(K$20:K$162),"",INDEX(K:K,SMALL(IF(K$20:K$162<>"", ROW($20:$162)),ROW(F4)))),"")} | L6: {=IFERROR(INDEX(L:L,SMALL(IF(L$20:L$177<>"", ROW($20:$177)),$A6)),"")} | M6: {=IFERROR(INDEX(M:M,SMALL(IF(M$20:M$177<>"", ROW($20:$177)),$A6)),"")} | N6: {=IFERROR(INDEX(N:N,SMALL(IF(N$20:N$177<>"", ROW($20:$177)),$A6)),"")} -> Manueller Backstop | O6: {=IFERROR(INDEX(O:O,SMALL(IF(O$20:O$177<>"", ROW($20:$177)),$A6)),"")} | P6: {=IFERROR(INDEX(P:P,SMALL(IF(P$20:P$177<>"", ROW($20:$177)),$A6)),"")} | Q6: {=IFERROR(INDEX(Q:Q,SMALL(IF(Q$20:Q$177<>"", ROW($20:$177)),$A6)),"")} | R6: {=IFERROR(INDEX(R:R,SMALL(IF(R$20:R$177<>"", ROW($20:$177)),$A6)),"")} | S6: {=IFERROR(INDEX(S:S,SMALL(IF(S$20:S$177<>"", ROW($20:$177)),$A6)),"")} | T6: {=IFERROR(INDEX(T:T,SMALL(IF(T$20:T$177<>"", ROW($20:$177)),$A6)),"")} | U6: {=IFERROR(INDEX(U:U,SMALL(IF(U$20:U$177<>"", ROW($20:$177)),$A6)),"")} | V6: {=IFERROR(INDEX(V:V,SMALL(IF(V$20:V$177<>"", ROW($20:$177)),$A6)),"")} | W6: {=IFERROR(INDEX(W:W,SMALL(IF(W$20:W$177<>"", ROW($20:$177)),$A6)),"")}
